Workbook
Name NativeTimeline_Order_Date: #N/A
Name Slicer_Category: #N/A
Name Slicer_Loyalty_Level: #N/A
Name Slicer_Payment_Type: #N/A
Name Slicer_Region: #N/A
Name Slicer_Store_Type: #N/A

Sheet Sales_Fact
A1: Sales_ID | B1: Order_Date | C1: Customer_ID | D1: Product_ID | E1: Store_ID | F1: Quantity | G1: Unit_Price | H1: Discount | I1: Payment_Type | J1: Total_Amount | K1: Quantity2 | L1: Unit_Price3 | M1: Discount4 | N1: Total_Amount5 | O1: Gross Amount | P1: Discounted Amount | Q1: Order Value Category
A2: SALE0 | B2: 45480 | C2: CUST1409 | D2: PROD97 | E2: STORE3 | F2: 1 | G2: 218.04 | H2: 0.09 | I2: Credit Card | J2: 198.4164 | K2: =IF(ISBLANK(Sales_Fact[[#This Row],[Quantity]]),MEDIAN(Sales_Fact[Quantity]),Sales_Fact[[#This Row],[Quantity]]) -> 1 | L2: =IF(ISBLANK(Sales_Fact[[#This Row],[Unit_Price]]),MEDIAN(Sales_Fact[Unit_Price]),Sales_Fact[[#This Row],[Unit_Price]]) -> 218.04 | M2: =IF(ISBLANK(Sales_Fact[[#This Row],[Discount]]),MEDIAN(Sales_Fact[Discount]),Sales_Fact[[#This Row],[Discount]]) -> 0.09 | N2: =Sales_Fact[[#This Row],[Quantity2]]*Sales_Fact[[#This Row],[Unit_Price3]]*(1-Sales_Fact[[#This Row],[Discount4]]) -> 198.4164 | O2: =Sales_Fact[[#This Row],[Quantity2]]*Sales_Fact[[#This Row],[Unit_Price3]] -> 218.04 | P2: =Sales_Fact[[#This Row],[Gross Amount]]*Sales_Fact[[#This Row],[Discount4]] -> 19.6236 | Q2: =IF(Sales_Fact[[#This Row],[Total_Amount5]]>1000,"High Value","Standard") -> Standard
A3: SALE1 | B3: 45285 | C3: CUST1467 | D3: PROD74 | E3: STORE17 | F3: 3 | G3: 104.47 | H3: 0.27 | I3: PayPal | J3: 228.7893 | K3: =IF(ISBLANK(Sales_Fact[[#This Row],[Quantity]]),MEDIAN(Sales_Fact[Quantity]),Sales_Fact[[#This Row],[Quantity]]) -> 3 | L3: =IF(ISBLANK(Sales_Fact[[#This Row],[Unit_Price]]),MEDIAN(Sales_Fact[Unit_Price]),Sales_Fact[[#This Row],[Unit_Price]]) -> 104.47 | M3: =IF(ISBLANK(Sales_Fact[[#This Row],[Discount]]),MEDIAN(Sales_Fact[Discount]),Sales_Fact[[#This Row],[Discount]]) -> 0.27 | N3: =Sales_Fact[[#This Row],[Quantity2]]*Sales_Fact[[#This Row],[Unit_Price3]]*(1-Sales_Fact[[#This Row],[Discount4]]) -> 228.7893 | O3: =Sales_Fact[[#This Row],[Quantity2]]*Sales_Fact[[#This Row],[Unit_Price3]] -> 313.41 | P3: =Sales_Fact[[#This Row],[Gross Amount]]*Sales_Fact[[#This Row],[Discount4]] -> 84.6207 | Q3: =IF(Sales_Fact[[#This Row],[Total_Amount5]]>1000,"High Value","Standard") -> Standard
A4: SALE2 | B4: 45446 | C4: CUST1056 | D4: PROD49 | E4: STORE8 | F4: 4 | G4: 914.05 | H4: 0.25 | I4: Credit Card | J4: 2742.15 | K4: =IF(ISBLANK(Sales_Fact[[#This Row],[Quantity]]),MEDIAN(Sales_Fact[Quantity]),Sales_Fact[[#This Row],[Quantity]]) -> 4 | L4: =IF(ISBLANK(Sales_Fact[[#This Row],[Unit_Price]]),MEDIAN(Sales_Fact[Unit_Price]),Sales_Fact[[#This Row],[Unit_Price]]) -> 914.05 | M4: =IF(ISBLANK(Sales_Fact[[#This Row],[Discount]]),MEDIAN(Sales_Fact[Discount]),Sales_Fact[[#This Row],[Discount]]) -> 0.25 | N4: =Sales_Fact[[#This Row],[Quantity2]]*Sales_Fact[[#This Row],[Unit_Price3]]*(1-Sales_Fact[[#This Row],[Discount4]]) -> 2742.15 | O4: =Sales_Fact[[#This Row],[Quantity2]]*Sales_Fact[[#This Row],[Unit_Price3]] -> 3656.2 | P4: =Sales_Fact[[#This Row],[Gross Amount]]*Sales_Fact[[#This Row],[Discount4]] -> 914.05 | Q4: =IF(Sales_Fact[[#This Row],[Total_Amount5]]>1000,"High Value","Standard") -> High Value
A5: SALE3 | B5: 45259 | C5: CUST1346 | D5: PROD76 | E5: STORE8 | F5: 1 | G5: 921.51 | H5: 0.16 | I5: COD | J5: 774.0684 | K5: =IF(ISBLANK(Sales_Fact[[#This Row],[Quantity]]),MEDIAN(Sales_Fact[Quantity]),Sales_Fact[[#This Row],[Quantity]]) -> 1 | L5: =IF(ISBLANK(Sales_Fact[[#This Row],[Unit_Price]]),MEDIAN(Sales_Fact[Unit_Price]),Sales_Fact[[#This Row],[Unit_Price]]) -> 921.51 | M5: =IF(ISBLANK(Sales_Fact[[#This Row],[Discount]]),MEDIAN(Sales_Fact[Discount]),Sales_Fact[[#This Row],[Discount]]) -> 0.16 | N5: =Sales_Fact[[#This Row],[Quantity2]]*Sales_Fact[[#This Row],[Unit_Price3]]*(1-Sales_Fact[[#This Row],[Discount4]]) -> 774.0684 | O5: =Sales_Fact[[#This Row],[Quantity2]]*Sales_Fact[[#This Row],[Unit_Price3]] -> 921.51 | P5: =Sales_Fact[[#This Row],[Gross Amount]]*Sales_Fact[[#This Row],[Discount4]] -> 147.4416 | Q5: =IF(Sales_Fact[[#This Row],[Total_Amount5]]>1000,"High Value","Standard") -> Standard
A6: SALE4 | B6: 45297 | C6: CUST1493 | D6: PROD59 | E6: STORE5 | F6: 3 | G6: 745.3 | H6: 0.18 | I6: Credit Card | J6: 1833.438 | K6: =IF(ISBLANK(Sales_Fact[[#This Row],[Quantity]]),MEDIAN(Sales_Fact[Quantity]),Sales_Fact[[#This Row],[Quantity]]) -> 3 | L6: =IF(ISBLANK(Sales_Fact[[#This Row],[Unit_Price]]),MEDIAN(Sales_Fact[Unit_Price]),Sales_Fact[[#This Row],[Unit_Price]]) -> 745.3 | M6: =IF(ISBLANK(Sales_Fact[[#This Row],[Discount]]),MEDIAN(Sales_Fact[Discount]),Sales_Fact[[#This Row],[Discount]]) -> 0.18 | N6: =Sales_Fact[[#This Row],[Quantity2]]*Sales_Fact[[#This Row],[Unit_Price3]]*(1-Sales_Fact[[#This Row],[Discount4]]) -> 1833.438 | O6: =Sales_Fact[[#This Row],[Quantity2]]*Sales_Fact[[#This Row],[Unit_Price3]] -> 2235.9 | P6: =Sales_Fact[[#This Row],[Gross Amount]]*Sales_Fact[[#This Row],[Discount4]] -> 402.462 | Q6: =IF(Sales_Fact[[#This Row],[Total_Amount5]]>1000,"High Value","Standard") -> High Value
A7: SALE5 | B7: 45499 | C7: CUST1116 | D7: PROD15 | E7: STORE7 | F7: 3 | G7: 147.01 | H7: 0.19 | I7: COD | J7: 357.2343 | K7: =IF(ISBLANK(Sales_Fact[[#This Row],[Quantity]]),MEDIAN(Sales_Fact[Quantity]),Sales_Fact[[#This Row],[Quantity]]) -> 3 | L7: =IF(ISBLANK(Sales_Fact[[#This Row],[Unit_Price]]),MEDIAN(Sales_Fact[Unit_Price]),Sales_Fact[[#This Row],[Unit_Price]]) -> 147.01 | M7: =IF(ISBLANK(Sales_Fact[[#This Row],[Discount]]),MEDIAN(Sales_Fact[Discount]),Sales_Fact[[#This Row],[Discount]]) -> 0.19 | N7: =Sales_Fact[[#This Row],[Quantity2]]*Sales_Fact[[#This Row],[Unit_Price3]]*(1-Sales_Fact[[#This Row],[Discount4]]) -> 357.2343 | O7: =Sales_Fact[[#This Row],[Quantity2]]*Sales_Fact[[#This Row],[Unit_Price3]] -> 441.03 | P7: =Sales_Fact[[#This Row],[Gross Amount]]*Sales_Fact[[#This Row],[Discount4]] -> 83.7957 | Q7: =IF(Sales_Fact[[#This Row],[Total_Amount5]]>1000,"High Value","Standard") -> Standard
A8: SALE6 | B8: 45850 | C8: CUST1016 | D8: PROD56 | E8: STORE4 | F8: 2 | G8: 785.31 | H8: 0.15 | I8: PayPal | J8: 1335.027 | K8: =IF(ISBLANK(Sales_Fact[[#This Row],[Quantity]]),MEDIAN(Sales_Fact[Quantity]),Sales_Fact[[#This Row],[Quantity]]) -> 2 | L8: =IF(ISBLANK(Sales_Fact[[#This Row],[Unit_Price]]),MEDIAN(Sales_Fact[Unit_Price]),Sales_Fact[[#This Row],[Unit_Price]]) -> 785.31 | M8: =IF(ISBLANK(Sales_Fact[[#This Row],[Discount]]),MEDIAN(Sales_Fact[Discount]),Sales_Fact[[#This Row],[Discount]]) -> 0.15 | N8: =Sales_Fact[[#This Row],[Quantity2]]*Sales_Fact[[#This Row],[Unit_Price3]]*(1-Sales_Fact[[#This Row],[Discount4]]) -> 1335.027 | O8: =Sales_Fact[[#This Row],[Quantity2]]*Sales_Fact[[#This Row],[Unit_Price3]] -> 1570.62 | P8: =Sales_Fact[[#This Row],[Gross Amount]]*Sales_Fact[[#This Row],[Discount4]] -> 235.593 | Q8: =IF(Sales_Fact[[#This Row],[Total_Amount5]]>1000,"High Value","Standard") -> High Value
A9: SALE7 | B9: 45248 | C9: CUST1152 | D9: PROD70 | E9: STORE8 | F9: 4 | G9: 342.39 | H9: 0.23 | I9: PayPal | J9: 1054.5612 | K9: =IF(ISBLANK(Sales_Fact[[#This Row],[Quantity]]),MEDIAN(Sales_Fact[Quantity]),Sales_Fact[[#This Row],[Quantity]]) -> 4 | L9: =IF(ISBLANK(Sales_Fact[[#This Row],[Unit_Price]]),MEDIAN(Sales_Fact[Unit_Price]),Sales_Fact[[#This Row],[Unit_Price]]) -> 342.39 | M9: =IF(ISBLANK(Sales_Fact[[#This Row],[Discount]]),MEDIAN(Sales_Fact[Discount]),Sales_Fact[[#This Row],[Discount]]) -> 0.23 | N9: =Sales_Fact[[#This Row],[Quantity2]]*Sales_Fact[[#This Row],[Unit_Price3]]*(1-Sales_Fact[[#This Row],[Discount4]]) -> 1054.5612 | O9: =Sales_Fact[[#This Row],[Quantity2]]*Sales_Fact[[#This Row],[Unit_Price3]] -> 1369.56 | P9: =Sales_Fact[[#This Row],[Gross Amount]]*Sales_Fact[[#This Row],[Discount4]] -> 314.9988 | Q9: =IF(Sales_Fact[[#This Row],[Total_Amount5]]>1000,"High Value","Standard") -> High Value
A10: SALE8 | B10: 45781 | C10: CUST1187 | D10: PROD99 | E10: STORE5 | G10: 448.25 | H10: 0.07 | I10: PayPal | J10: 1250.6175 | K10: =IF(ISBLANK(Sales_Fact[[#This Row],[Quantity]]),MEDIAN(Sales_Fact[Quantity]),Sales_Fact[[#This Row],[Quantity]]) -> 2 | L10: =IF(ISBLANK(Sales_Fact[[#This Row],[Unit_Price]]),MEDIAN(Sales_Fact[Unit_Price]),Sales_Fact[[#This Row],[Unit_Price]]) -> 448.25 | M10: =IF(ISBLANK(Sales_Fact[[#This Row],[Discount]]),MEDIAN(Sales_Fact[Discount]),Sales_Fact[[#This Row],[Discount]]) -> 0.07 | N10: =Sales_Fact[[#This Row],[Quantity2]]*Sales_Fact[[#This Row],[Unit_Price3]]*(1-Sales_Fact[[#This Row],[Discount4]]) -> 833.745 | O10: =Sales_Fact[[#This Row],[Quantity2]]*Sales_Fact[[#This Row],[Unit_Price3]] -> 896.5 | P10: =Sales_Fact[[#This Row],[Gross Amount]]*Sales_Fact[[#This Row],[Discount4]] -> 62.755 | Q10: =IF(Sales_Fact[[#This Row],[Total_Amount5]]>1000,"High Value","Standard") -> Standard
A11: SALE9 | B11: 45869 | C11: CUST1464 | D11: PROD33 | E11: STORE0 | F11: 2 | G11: 873.17 | H11: 0.23 | I11: PayPal | J11: 1344.6818 | K11: =IF(ISBLANK(Sales_Fact[[#This Row],[Quantity]]),MEDIAN(Sales_Fact[Quantity]),Sales_Fact[[#This Row],[Quantity]]) -> 2 | L11: =IF(ISBLANK(Sales_Fact[[#This Row],[Unit_Price]]),MEDIAN(Sales_Fact[Unit_Price]),Sales_Fact[[#This Row],[Unit_Price]]) -> 873.17 | M11: =IF(ISBLANK(Sales_Fact[[#This Row],[Discount]]),MEDIAN(Sales_Fact[Discount]),Sales_Fact[[#This Row],[Discount]]) -> 0.23 | N11: =Sales_Fact[[#This Row],[Quantity2]]*Sales_Fact[[#This Row],[Unit_Price3]]*(1-Sales_Fact[[#This Row],[Discount4]]) -> 1344.6818 | O11: =Sales_Fact[[#This Row],[Quantity2]]*Sales_Fact[[#This Row],[Unit_Price3]] -> 1746.34 | P11: =Sales_Fact[[#This Row],[Gross Amount]]*Sales_Fact[[#This Row],[Discount4]] -> 401.6582 | Q11: =IF(Sales_Fact[[#This Row],[Total_Amount5]]>1000,"High Value","Standard") -> High Value
A12: SALE10 | B12: 45335 | C12: CUST1065 | D12: PROD24 | E12: STORE14 | F12: 1 | G12: 278.63 | H12: 0.07 | I12: Credit Card | J12: 259.1259 | K12: =IF(ISBLANK(Sales_Fact[[#This Row],[Quantity]]),MEDIAN(Sales_Fact[Quantity]),Sales_Fact[[#This Row],[Quantity]]) -> 1 | L12: =IF(ISBLANK(Sales_Fact[[#This Row],[Unit_Price]]),MEDIAN(Sales_Fact[Unit_Price]),Sales_Fact[[#This Row],[Unit_Price]]) -> 278.63 | M12: =IF(ISBLANK(Sales_Fact[[#This Row],[Discount]]),MEDIAN(Sales_Fact[Discount]),Sales_Fact[[#This Row],[Discount]]) -> 0.07 | N12: =Sales_Fact[[#This Row],[Quantity2]]*Sales_Fact[[#This Row],[Unit_Price3]]*(1-Sales_Fact[[#This Row],[Discount4]]) -> 259.1259 | O12: =Sales_Fact[[#This Row],[Quantity2]]*Sales_Fact[[#This Row],[Unit_Price3]] -> 278.63 | P12: =Sales_Fact[[#This Row],[Gross Amount]]*Sales_Fact[[#This Row],[Discount4]] -> 19.5041 | Q12: =IF(Sales_Fact[[#This Row],[Total_Amount5]]>1000,"High Value","Standard") -> Standard
A13: SALE11 | B13: 45801 | C13: CUST1320 | D13: PROD39 | E13: STORE1 | F13: 4 | G13: 286.92 | H13: 0.17 | I13: Credit Card | J13: 952.5744 | K13: =IF(ISBLANK(Sales_Fact[[#This Row],[Quantity]]),MEDIAN(Sales_Fact[Quantity]),Sales_Fact[[#This Row],[Quantity]]) -> 4 | L13: =IF(ISBLANK(Sales_Fact[[#This Row],[Unit_Price]]),MEDIAN(Sales_Fact[Unit_Price]),Sales_Fact[[#This Row],[Unit_Price]]) -> 286.92 | M13: =IF(ISBLANK(Sales_Fact[[#This Row],[Discount]]),MEDIAN(Sales_Fact[Discount]),Sales_Fact[[#This Row],[Discount]]) -> 0.17 | N13: =Sales_Fact[[#This Row],[Quantity2]]*Sales_Fact[[#This Row],[Unit_Price3]]*(1-Sales_Fact[[#This Row],[Discount4]]) -> 952.5744 | O13: =Sales_Fact[[#This Row],[Quantity2]]*Sales_Fact[[#This Row],[Unit_Price3]] -> 1147.68 | P13: =Sales_Fact[[#This Row],[Gross Amount]]*Sales_Fact[[#This Row],[Discount4]] -> 195.1056 | Q13: =IF(Sales_Fact[[#This Row],[Total_Amount5]]>1000,"High Value","Standard") -> Standard
A14: SALE12 | B14: 45528 | C14: CUST1237 | D14: PROD88 | E14: STORE4 | F14: 4 | G14: 644.58 | H14: 0.01 | I14: Credit Card | J14: 2552.5368 | K14: =IF(ISBLANK(Sales_Fact[[#This Row],[Quantity]]),MEDIAN(Sales_Fact[Quantity]),Sales_Fact[[#This Row],[Quantity]]) -> 4 | L14: =IF(ISBLANK(Sales_Fact[[#This Row],[Unit_Price]]),MEDIAN(Sales_Fact[Unit_Price]),Sales_Fact[[#This Row],[Unit_Price]]) -> 644.58 | M14: =IF(ISBLANK(Sales_Fact[[#This Row],[Discount]]),MEDIAN(Sales_Fact[Discount]),Sales_Fact[[#This Row],[Discount]]) -> 0.01 | N14: =Sales_Fact[[#This Row],[Quantity2]]*Sales_Fact[[#This Row],[Unit_Price3]]*(1-Sales_Fact[[#This Row],[Discount4]]) -> 2552.5368 | O14: =Sales_Fact[[#This Row],[Quantity2]]*Sales_Fact[[#This Row],[Unit_Price3]] -> 2578.32 | P14: =Sales_Fact[[#This Row],[Gross Amount]]*Sales_Fact[[#This Row],[Discount4]] -> 25.7832 | Q14: =IF(Sales_Fact[[#This Row],[Total_Amount5]]>1000,"High Value","Standard") -> High Value
A15: SALE13 | B15: 45875 | C15: CUST1443 | D15: PROD34 | E15: STORE16 | F15: 2 | G15: 316.9 | H15: 0.3 | I15: PayPal | J15: 443.66 | K15: =IF(ISBLANK(Sales_Fact[[#This Row],[Quantity]]),MEDIAN(Sales_Fact[Quantity]),Sales_Fact[[#This Row],[Quantity]]) -> 2 | L15: =IF(ISBLANK(Sales_Fact[[#This Row],[Unit_Price]]),MEDIAN(Sales_Fact[Unit_Price]),Sales_Fact[[#This Row],[Unit_Price]]) -> 316.9 | M15: =IF(ISBLANK(Sales_Fact[[#This Row],[Discount]]),MEDIAN(Sales_Fact[Discount]),Sales_Fact[[#This Row],[Discount]]) -> 0.3 | N15: =Sales_Fact[[#This Row],[Quantity2]]*Sales_Fact[[#This Row],[Unit_Price3]]*(1-Sales_Fact[[#This Row],[Discount4]]) -> 443.66 | O15: =Sales_Fact[[#This Row],[Quantity2]]*Sales_Fact[[#This Row],[Unit_Price3]] -> 633.8 | P15: =Sales_Fact[[#This Row],[Gross Amount]]*Sales_Fact[[#This Row],[Discount4]] -> 190.14 | Q15: =IF(Sales_Fact[[#This Row],[Total_Amount5]]>1000,"High Value","Standard") -> Standard
A16: SALE14 | B16: 45829 | C16: CUST1348 | D16: PROD24 | E16: STORE15 | F16: 4 | G16: 403.47 | H16: 0.29 | I16: PayPal | J16: 1145.8548 | K16: =IF(ISBLANK(Sales_Fact[[#This Row],[Quantity]]),MEDIAN(Sales_Fact[Quantity]),Sales_Fact[[#This Row],[Quantity]]) -> 4 | L16: =IF(ISBLANK(Sales_Fact[[#This Row],[Unit_Price]]),MEDIAN(Sales_Fact[Unit_Price]),Sales_Fact[[#This Row],[Unit_Price]]) -> 403.47 | M16: =IF(ISBLANK(Sales_Fact[[#This Row],[Discount]]),MEDIAN(Sales_Fact[Discount]),Sales_Fact[[#This Row],[Discount]]) -> 0.29 | N16: =Sales_Fact[[#This Row],[Quantity2]]*Sales_Fact[[#This Row],[Unit_Price3]]*(1-Sales_Fact[[#This Row],[Discount4]]) -> 1145.8548 | O16: =Sales_Fact[[#This Row],[Quantity2]]*Sales_Fact[[#This Row],[Unit_Price3]] -> 1613.88 | P16: =Sales_Fact[[#This Row],[Gross Amount]]*Sales_Fact[[#This Row],[Discount4]] -> 468.0252 | Q16: =IF(Sales_Fact[[#This Row],[Total_Amount5]]>1000,"High Value","Standard") -> High Value
A17: SALE15 | B17: 45636 | C17: CUST1435 | D17: PROD36 | E17: STORE9 | G17: 871.34 | H17: 0.04 | I17: COD | J17: 2509.4592 | K17: =IF(ISBLANK(Sales_Fact[[#This Row],[Quantity]]),MEDIAN(Sales_Fact[Quantity]),Sales_Fact[[#This Row],[Quantity]]) -> 2 | L17: =IF(ISBLANK(Sales_Fact[[#This Row],[Unit_Price]]),MEDIAN(Sales_Fact[Unit_Price]),Sales_Fact[[#This Row],[Unit_Price]]) -> 871.34 | M17: =IF(ISBLANK(Sales_Fact[[#This Row],[Discount]]),MEDIAN(Sales_Fact[Discount]),Sales_Fact[[#This Row],[Discount]]) -> 0.04 | N17: =Sales_Fact[[#This Row],[Quantity2]]*Sales_Fact[[#This Row],[Unit_Price3]]*(1-Sales_Fact[[#This Row],[Discount4]]) -> 1672.9728 | O17: =Sales_Fact[[#This Row],[Quantity2]]*Sales_Fact[[#This Row],[Unit_Price3]] -> 1742.68 | P17: =Sales_Fact[[#This Row],[Gross Amount]]*Sales_Fact[[#This Row],[Discount4]] -> 69.7072 | Q17: =IF(Sales_Fact[[#This Row],[Total_Amount5]]>1000,"High Value","Standard") -> High Value
A18: SALE16 | B18: 45913 | C18: CUST1276 | D18: PROD65 | E18: STORE19 | F18: 2 | G18: 451.98 | H18: 0.25 | I18: Credit Card | J18: 677.97 | K18: =IF(ISBLANK(Sales_Fact[[#This Row],[Quantity]]),MEDIAN(Sales_Fact[Quantity]),Sales_Fact[[#This Row],[Quantity]]) -> 2 | L18: =IF(ISBLANK(Sales_Fact[[#This Row],[Unit_Price]]),MEDIAN(Sales_Fact[Unit_Price]),Sales_Fact[[#This Row],[Unit_Price]]) -> 451.98 | M18: =IF(ISBLANK(Sales_Fact[[#This Row],[Discount]]),MEDIAN(Sales_Fact[Discount]),Sales_Fact[[#This Row],[Discount]]) -> 0.25 | N18: =Sales_Fact[[#This Row],[Quantity2]]*Sales_Fact[[#This Row],[Unit_Price3]]*(1-Sales_Fact[[#This Row],[Discount4]]) -> 677.97 | O18: =Sales_Fact[[#This Row],[Quantity2]]*Sales_Fact[[#This Row],[Unit_Price3]] -> 903.96 | P18: =Sales_Fact[[#This Row],[Gross Amount]]*Sales_Fact[[#This Row],[Discount4]] -> 225.99 | Q18: =IF(Sales_Fact[[#This Row],[Total_Amount5]]>1000,"High Value","Standard") -> Standard
A19: SALE17 | B19: 45637 | C19: CUST1079 | D19: PROD27 | E19: STORE4 | F19: 2 | G19: 502.69 | H19: 0.23 | I19: Credit Card | J19: 774.1426 | K19: =IF(ISBLANK(Sales_Fact[[#This Row],[Quantity]]),MEDIAN(Sales_Fact[Quantity]),Sales_Fact[[#This Row],[Quantity]]) -> 2 | L19: =IF(ISBLANK(Sales_Fact[[#This Row],[Unit_Price]]),MEDIAN(Sales_Fact[Unit_Price]),Sales_Fact[[#This Row],[Unit_Price]]) -> 502.69 | M19: =IF(ISBLANK(Sales_Fact[[#This Row],[Discount]]),MEDIAN(Sales_Fact[Discount]),Sales_Fact[[#This Row],[Discount]]) -> 0.23 | N19: =Sales_Fact[[#This Row],[Quantity2]]*Sales_Fact[[#This Row],[Unit_Price3]]*(1-Sales_Fact[[#This Row],[Discount4]]) -> 774.1426 | O19: =Sales_Fact[[#This Row],[Quantity2]]*Sales_Fact[[#This Row],[Unit_Price3]] -> 1005.38 | P19: =Sales_Fact[[#This Row],[Gross Amount]]*Sales_Fact[[#This Row],[Discount4]] -> 231.2374 | Q19: =IF(Sales_Fact[[#This Row],[Total_Amount5]]>1000,"High Value","Standard") -> Standard
A20: SALE18 | B20: 45517 | C20: CUST1094 | D20: PROD39 | E20: STORE4 | F20: 2 | G20: 559.23 | H20: 0.25 | I20: COD | J20: 838.845 | K20: =IF(ISBLANK(Sales_Fact[[#This Row],[Quantity]]),MEDIAN(Sales_Fact[Quantity]),Sales_Fact[[#This Row],[Quantity]]) -> 2 | L20: =IF(ISBLANK(Sales_Fact[[#This Row],[Unit_Price]]),MEDIAN(Sales_Fact[Unit_Price]),Sales_Fact[[#This Row],[Unit_Price]]) -> 559.23 | M20: =IF(ISBLANK(Sales_Fact[[#This Row],[Discount]]),MEDIAN(Sales_Fact[Discount]),Sales_Fact[[#This Row],[Discount]]) -> 0.25 | N20: =Sales_Fact[[#This Row],[Quantity2]]*Sales_Fact[[#This Row],[Unit_Price3]]*(1-Sales_Fact[[#This Row],[Discount4]]) -> 838.845 | O20: =Sales_Fact[[#This Row],[Quantity2]]*Sales_Fact[[#This Row],[Unit_Price3]] -> 1118.46 | P20: =Sales_Fact[[#This Row],[Gross Amount]]*Sales_Fact[[#This Row],[Discount4]] -> 279.615 | Q20: =IF(Sales_Fact[[#This Row],[Total_Amount5]]>1000,"High Value","Standard") -> Standard
A21: SALE19 | B21: 45369 | C21: CUST1239 | D21: PROD60 | E21: STORE13 | F21: 4 | H21: 0.04 | I21: COD | J21: 1782.4512 | K21: =IF(ISBLANK(Sales_Fact[[#This Row],[Quantity]]),MEDIAN(Sales_Fact[Quantity]),Sales_Fact[[#This Row],[Quantity]]) -> 4 | L21: =IF(ISBLANK(Sales_Fact[[#This Row],[Unit_Price]]),MEDIAN(Sales_Fact[Unit_Price]),Sales_Fact[[#This Row],[Unit_Price]]) -> 522.72 | M21: =IF(ISBLANK(Sales_Fact[[#This Row],[Discount]]),MEDIAN(Sales_Fact[Discount]),Sales_Fact[[#This Row],[Discount]]) -> 0.04 | N21: =Sales_Fact[[#This Row],[Quantity2]]*Sales_Fact[[#This Row],[Unit_Price3]]*(1-Sales_Fact[[#This Row],[Discount4]]) -> 2007.2448 | O21: =Sales_Fact[[#This Row],[Quantity2]]*Sales_Fact[[#This Row],[Unit_Price3]] -> 2090.88 | P21: =Sales_Fact[[#This Row],[Gross Amount]]*Sales_Fact[[#This Row],[Discount4]] -> 83.6352 | Q21: =IF(Sales_Fact[[#This Row],[Total_Amount5]]>1000,"High Value","Standard") -> High Value
A22: SALE20 | B22: 45843 | C22: CUST1144 | D22: PROD72 | E22: STORE17 | F22: 3 | G22: 986.04 | H22: 0.27 | I22: COD | J22: 2159.4276 | K22: =IF(ISBLANK(Sales_Fact[[#This Row],[Quantity]]),MEDIAN(Sales_Fact[Quantity]),Sales_Fact[[#This Row],[Quantity]]) -> 3 | L22: =IF(ISBLANK(Sales_Fact[[#This Row],[Unit_Price]]),MEDIAN(Sales_Fact[Unit_Price]),Sales_Fact[[#This Row],[Unit_Price]]) -> 986.04 | M22: =IF(ISBLANK(Sales_Fact[[#This Row],[Discount]]),MEDIAN(Sales_Fact[Discount]),Sales_Fact[[#This Row],[Discount]]) -> 0.27 | N22: =Sales_Fact[[#This Row],[Quantity2]]*Sales_Fact[[#This Row],[Unit_Price3]]*(1-Sales_Fact[[#This Row],[Discount4]]) -> 2159.4276 | O22: =Sales_Fact[[#This Row],[Quantity2]]*Sales_Fact[[#This Row],[Unit_Price3]] -> 2958.12 | P22: =Sales_Fact[[#This Row],[Gross Amount]]*Sales_Fact[[#This Row],[Discount4]] -> 798.6924 | Q22: =IF(Sales_Fact[[#This Row],[Total_Amount5]]>1000,"High Value","Standard") -> High Value
A23: SALE21 | B23: 45447 | C23: CUST1396 | D23: PROD43 | E23: STORE18 | F23: 1 | G23: 589.56 | H23: 0.22 | I23: Credit Card | J23: 459.8568 | K23: =IF(ISBLANK(Sales_Fact[[#This Row],[Quantity]]),MEDIAN(Sales_Fact[Quantity]),Sales_Fact[[#This Row],[Quantity]]) -> 1 | L23: =IF(ISBLANK(Sales_Fact[[#This Row],[Unit_Price]]),MEDIAN(Sales_Fact[Unit_Price]),Sales_Fact[[#This Row],[Unit_Price]]) -> 589.56 | M23: =IF(ISBLANK(Sales_Fact[[#This Row],[Discount]]),MEDIAN(Sales_Fact[Discount]),Sales_Fact[[#This Row],[Discount]]) -> 0.22 | N23: =Sales_Fact[[#This Row],[Quantity2]]*Sales_Fact[[#This Row],[Unit_Price3]]*(1-Sales_Fact[[#This Row],[Discount4]]) -> 459.8568 | O23: =Sales_Fact[[#This Row],[Quantity2]]*Sales_Fact[[#This Row],[Unit_Price3]] -> 589.56 | P23: =Sales_Fact[[#This Row],[Gross Amount]]*Sales_Fact[[#This Row],[Discount4]] -> 129.7032 | Q23: =IF(Sales_Fact[[#This Row],[Total_Amount5]]>1000,"High Value","Standard") -> Standard
A24: SALE22 | B24: 45394 | C24: CUST1476 | D24: PROD69 | E24: STORE10 | F24: 3 | G24: 979.42 | H24: 0.03 | I24: PayPal | J24: 2850.1122 | K24: =IF(ISBLANK(Sales_Fact[[#This Row],[Quantity]]),MEDIAN(Sales_Fact[Quantity]),Sales_Fact[[#This Row],[Quantity]]) -> 3 | L24: =IF(ISBLANK(Sales_Fact[[#This Row],[Unit_Price]]),MEDIAN(Sales_Fact[Unit_Price]),Sales_Fact[[#This Row],[Unit_Price]]) -> 979.42 | M24: =IF(ISBLANK(Sales_Fact[[#This Row],[Discount]]),MEDIAN(Sales_Fact[Discount]),Sales_Fact[[#This Row],[Discount]]) -> 0.03 | N24: =Sales_Fact[[#This Row],[Quantity2]]*Sales_Fact[[#This Row],[Unit_Price3]]*(1-Sales_Fact[[#This Row],[Discount4]]) -> 2850.1122 | O24: =Sales_Fact[[#This Row],[Quantity2]]*Sales_Fact[[#This Row],[Unit_Price3]] -> 2938.26 | P24: =Sales_Fact[[#This Row],[Gross Amount]]*Sales_Fact[[#This Row],[Discount4]] -> 88.1478 | Q24: =IF(Sales_Fact[[#This Row],[Total_Amount5]]>1000,"High Value","Standard") -> High Value
A25: SALE23 | B25: 45466 | C25: CUST1368 | D25: PROD12 | E25: STORE8 | F25: 1 | G25: 719.28 | H25: 0.08 | I25: Credit Card | J25: 661.7376 | K25: =IF(ISBLANK(Sales_Fact[[#This Row],[Quantity]]),MEDIAN(Sales_Fact[Quantity]),Sales_Fact[[#This Row],[Quantity]]) -> 1 | L25: =IF(ISBLANK(Sales_Fact[[#This Row],[Unit_Price]]),MEDIAN(Sales_Fact[Unit_Price]),Sales_Fact[[#This Row],[Unit_Price]]) -> 719.28 | M25: =IF(ISBLANK(Sales_Fact[[#This Row],[Discount]]),MEDIAN(Sales_Fact[Discount]),Sales_Fact[[#This Row],[Discount]]) -> 0.08 | N25: =Sales_Fact[[#This Row],[Quantity2]]*Sales_Fact[[#This Row],[Unit_Price3]]*(1-Sales_Fact[[#This Row],[Discount4]]) -> 661.7376 | O25: =Sales_Fact[[#This Row],[Quantity2]]*Sales_Fact[[#This Row],[Unit_Price3]] -> 719.28 | P25: =Sales_Fact[[#This Row],[Gross Amount]]*Sales_Fact[[#This Row],[Discount4]] -> 57.5424 | Q25: =IF(Sales_Fact[[#This Row],[Total_Amount5]]>1000,"High Value","Standard") -> Standard
A26: SALE24 | B26: 45908 | C26: CUST1186 | D26: PROD67 | E26: STORE6 | F26: 3 | G26: 77.6 | H26: 0.07 | I26: Credit Card | J26: 216.504 | K26: =IF(ISBLANK(Sales_Fact[[#This Row],[Quantity]]),MEDIAN(Sales_Fact[Quantity]),Sales_Fact[[#This Row],[Quantity]]) -> 3 | L26: =IF(ISBLANK(Sales_Fact[[#This Row],[Unit_Price]]),MEDIAN(Sales_Fact[Unit_Price]),Sales_Fact[[#This Row],[Unit_Price]]) -> 77.6 | M26: =IF(ISBLANK(Sales_Fact[[#This Row],[Discount]]),MEDIAN(Sales_Fact[Discount]),Sales_Fact[[#This Row],[Discount]]) -> 0.07 | N26: =Sales_Fact[[#This Row],[Quantity2]]*Sales_Fact[[#This Row],[Unit_Price3]]*(1-Sales_Fact[[#This Row],[Discount4]]) -> 216.504 | O26: =Sales_Fact[[#This Row],[Quantity2]]*Sales_Fact[[#This Row],[Unit_Price3]] -> 232.8 | P26: =Sales_Fact[[#This Row],[Gross Amount]]*Sales_Fact[[#This Row],[Discount4]] -> 16.296 | Q26: =IF(Sales_Fact[[#This Row],[Total_Amount5]]>1000,"High Value","Standard") -> Standard
A27: SALE25 | B27: 45552 | C27: CUST1381 | D27: PROD5 | E27: STORE3 | F27: 4 | G27: 852.71 | H27: 0.14 | I27: PayPal | J27: 2933.3224 | K27: =IF(ISBLANK(Sales_Fact[[#This Row],[Quantity]]),MEDIAN(Sales_Fact[Quantity]),Sales_Fact[[#This Row],[Quantity]]) -> 4 | L27: =IF(ISBLANK(Sales_Fact[[#This Row],[Unit_Price]]),MEDIAN(Sales_Fact[Unit_Price]),Sales_Fact[[#This Row],[Unit_Price]]) -> 852.71 | M27: =IF(ISBLANK(Sales_Fact[[#This Row],[Discount]]),MEDIAN(Sales_Fact[Discount]),Sales_Fact[[#This Row],[Discount]]) -> 0.14 | N27: =Sales_Fact[[#This Row],[Quantity2]]*Sales_Fact[[#This Row],[Unit_Price3]]*(1-Sales_Fact[[#This Row],[Discount4]]) -> 2933.3224 | O27: =Sales_Fact[[#This Row],[Quantity2]]*Sales_Fact[[#This Row],[Unit_Price3]] -> 3410.84 | P27: =Sales_Fact[[#This Row],[Gross Amount]]*Sales_Fact[[#This Row],[Discount4]] -> 477.5176 | Q27: =IF(Sales_Fact[[#This Row],[Total_Amount5]]>1000,"High Value","Standard") -> High Value
A28: SALE26 | B28: 45294 | C28: CUST1213 | D28: PROD98 | E28: STORE8 | F28: 4 | G28: 156.16 | I28: Credit Card | J28: 599.6544 | K28: =IF(ISBLANK(Sales_Fact[[#This Row],[Quantity]]),MEDIAN(Sales_Fact[Quantity]),Sales_Fact[[#This Row],[Quantity]]) -> 4 | L28: =IF(ISBLANK(Sales_Fact[[#This Row],[Unit_Price]]),MEDIAN(Sales_Fact[Unit_Price]),Sales_Fact[[#This Row],[Unit_Price]]) -> 156.16 | M28: =IF(ISBLANK(Sales_Fact[[#This Row],[Discount]]),MEDIAN(Sales_Fact[Discount]),Sales_Fact[[#This Row],[Discount]]) -> 0.14 | N28: =Sales_Fact[[#This Row],[Quantity2]]*Sales_Fact[[#This Row],[Unit_Price3]]*(1-Sales_Fact[[#This Row],[Discount4]]) -> 537.1904 | O28: =Sales_Fact[[#This Row],[Quantity2]]*Sales_Fact[[#This Row],[Unit_Price3]] -> 624.64 | P28: =Sales_Fact[[#This Row],[Gross Amount]]*Sales_Fact[[#This Row],[Discount4]] -> 87.4496 | Q28: =IF(Sales_Fact[[#This Row],[Total_Amount5]]>1000,"High Value","Standard") -> Standard
A29: SALE27 | B29: 45710 | C29: CUST1200 | D29: PROD77 | E29: STORE8 | F29: 3 | G29: 815.49 | H29: 0.17 | I29: Credit Card | J29: 2030.5701 | K29: =IF(ISBLANK(Sales_Fact[[#This Row],[Quantity]]),MEDIAN(Sales_Fact[Quantity]),Sales_Fact[[#This Row],[Quantity]]) -> 3 | L29: =IF(ISBLANK(Sales_Fact[[#This Row],[Unit_Price]]),MEDIAN(Sales_Fact[Unit_Price]),Sales_Fact[[#This Row],[Unit_Price]]) -> 815.49 | M29: =IF(ISBLANK(Sales_Fact[[#This Row],[Discount]]),MEDIAN(Sales_Fact[Discount]),Sales_Fact[[#This Row],[Discount]]) -> 0.17 | N29: =Sales_Fact[[#This Row],[Quantity2]]*Sales_Fact[[#This Row],[Unit_Price3]]*(1-Sales_Fact[[#This Row],[Discount4]]) -> 2030.5701 | O29: =Sales_Fact[[#This Row],[Quantity2]]*Sales_Fact[[#This Row],[Unit_Price3]] -> 2446.47 | P29: =Sales_Fact[[#This Row],[Gross Amount]]*Sales_Fact[[#This Row],[Discount4]] -> 415.8999 | Q29: =IF(Sales_Fact[[#This Row],[Total_Amount5]]>1000,"High Value","Standard") -> High Value
A30: SALE28 | B30: 45923 | C30: CUST1148 | D30: PROD13 | E30: STORE2 | F30: 2 | G30: 74.21 | H30: 0.11 | I30: PayPal | J30: 132.0938 | K30: =IF(ISBLANK(Sales_Fact[[#This Row],[Quantity]]),MEDIAN(Sales_Fact[Quantity]),Sales_Fact[[#This Row],[Quantity]]) -> 2 | L30: =IF(ISBLANK(Sales_Fact[[#This Row],[Unit_Price]]),MEDIAN(Sales_Fact[Unit_Price]),Sales_Fact[[#This Row],[Unit_Price]]) -> 74.21 | M30: =IF(ISBLANK(Sales_Fact[[#This Row],[Discount]]),MEDIAN(Sales_Fact[Discount]),Sales_Fact[[#This Row],[Discount]]) -> 0.11 | N30: =Sales_Fact[[#This Row],[Quantity2]]*Sales_Fact[[#This Row],[Unit_Price3]]*(1-Sales_Fact[[#This Row],[Discount4]]) -> 132.0938 | O30: =Sales_Fact[[#This Row],[Quantity2]]*Sales_Fact[[#This Row],[Unit_Price3]] -> 148.42 | P30: =Sales_Fact[[#This Row],[Gross Amount]]*Sales_Fact[[#This Row],[Discount4]] -> 16.3262 | Q30: =IF(Sales_Fact[[#This Row],[Total_Amount5]]>1000,"High Value","Standard") -> Standard
A31: SALE29 | B31: 45302 | C31: CUST1348 | D31: PROD99 | E31: STORE3 | G31: 451.67 | H31: 0.15 | I31: Credit Card | J31: 1535.678 | K31: =IF(ISBLANK(Sales_Fact[[#This Row],[Quantity]]),MEDIAN(Sales_Fact[Quantity]),Sales_Fact[[#This Row],[Quantity]]) -> 2 | L31: =IF(ISBLANK(Sales_Fact[[#This Row],[Unit_Price]]),MEDIAN(Sales_Fact[Unit_Price]),Sales_Fact[[#This Row],[Unit_Price]]) -> 451.67 | M31: =IF(ISBLANK(Sales_Fact[[#This Row],[Discount]]),MEDIAN(Sales_Fact[Discount]),Sales_Fact[[#This Row],[Discount]]) -> 0.15 | N31: =Sales_Fact[[#This Row],[Quantity2]]*Sales_Fact[[#This Row],[Unit_Price3]]*(1-Sales_Fact[[#This Row],[Discount4]]) -> 767.839 | O31: =Sales_Fact[[#This Row],[Quantity2]]*Sales_Fact[[#This Row],[Unit_Price3]] -> 903.34 | P31: =Sales_Fact[[#This Row],[Gross Amount]]*Sales_Fact[[#This Row],[Discount4]] -> 135.501 | Q31: =IF(Sales_Fact[[#This Row],[Total_Amount5]]>1000,"High Value","Standard") -> Standard
A32: SALE30 | B32: 45217 | C32: CUST1028 | D32: PROD5 | E32: STORE19 | F32: 1 | G32: 429.38 | H32: 0.13 | I32: PayPal | J32: 373.5606 | K32: =IF(ISBLANK(Sales_Fact[[#This Row],[Quantity]]),MEDIAN(Sales_Fact[Quantity]),Sales_Fact[[#This Row],[Quantity]]) -> 1 | L32: =IF(ISBLANK(Sales_Fact[[#This Row],[Unit_Price]]),MEDIAN(Sales_Fact[Unit_Price]),Sales_Fact[[#This Row],[Unit_Price]]) -> 429.38 | M32: =IF(ISBLANK(Sales_Fact[[#This Row],[Discount]]),MEDIAN(Sales_Fact[Discount]),Sales_Fact[[#This Row],[Discount]]) -> 0.13 | N32: =Sales_Fact[[#This Row],[Quantity2]]*Sales_Fact[[#This Row],[Unit_Price3]]*(1-Sales_Fact[[#This Row],[Discount4]]) -> 373.5606 | O32: =Sales_Fact[[#This Row],[Quantity2]]*Sales_Fact[[#This Row],[Unit_Price3]] -> 429.38 | P32: =Sales_Fact[[#This Row],[Gross Amount]]*Sales_Fact[[#This Row],[Discount4]] -> 55.8194 | Q32: =IF(Sales_Fact[[#This Row],[Total_Amount5]]>1000,"High Value","Standard") -> Standard
A33: SALE31 | B33: 45593 | C33: CUST1412 | D33: PROD53 | E33: STORE12 | F33: 2 | G33: 148.96 | H33: 0.03 | I33: COD | J33: 288.9824 | K33: =IF(ISBLANK(Sales_Fact[[#This Row],[Quantity]]),MEDIAN(Sales_Fact[Quantity]),Sales_Fact[[#This Row],[Quantity]]) -> 2 | L33: =IF(ISBLANK(Sales_Fact[[#This Row],[Unit_Price]]),MEDIAN(Sales_Fact[Unit_Price]),Sales_Fact[[#This Row],[Unit_Price]]) -> 148.96 | M33: =IF(ISBLANK(Sales_Fact[[#This Row],[Discount]]),MEDIAN(Sales_Fact[Discount]),Sales_Fact[[#This Row],[Discount]]) -> 0.03 | N33: =Sales_Fact[[#This Row],[Quantity2]]*Sales_Fact[[#This Row],[Unit_Price3]]*(1-Sales_Fact[[#This Row],[Discount4]]) -> 288.9824 | O33: =Sales_Fact[[#This Row],[Quantity2]]*Sales_Fact[[#This Row],[Unit_Price3]] -> 297.92 | P33: =Sales_Fact[[#This Row],[Gross Amount]]*Sales_Fact[[#This Row],[Discount4]] -> 8.9376 | Q33: =IF(Sales_Fact[[#This Row],[Total_Amount5]]>1000,"High Value","Standard") -> Standard
A34: SALE32 | B34: 45597 | C34: CUST1398 | D34: PROD75 | E34: STORE8 | F34: 4 | G34: 313.83 | H34: 0.08 | I34: Credit Card | J34: 1154.8944 | K34: =IF(ISBLANK(Sales_Fact[[#This Row],[Quantity]]),MEDIAN(Sales_Fact[Quantity]),Sales_Fact[[#This Row],[Quantity]]) -> 4 | L34: =IF(ISBLANK(Sales_Fact[[#This Row],[Unit_Price]]),MEDIAN(Sales_Fact[Unit_Price]),Sales_Fact[[#This Row],[Unit_Price]]) -> 313.83 | M34: =IF(ISBLANK(Sales_Fact[[#This Row],[Discount]]),MEDIAN(Sales_Fact[Discount]),Sales_Fact[[#This Row],[Discount]]) -> 0.08 | N34: =Sales_Fact[[#This Row],[Quantity2]]*Sales_Fact[[#This Row],[Unit_Price3]]*(1-Sales_Fact[[#This Row],[Discount4]]) -> 1154.8944 | O34: =Sales_Fact[[#This Row],[Quantity2]]*Sales_Fact[[#This Row],[Unit_Price3]] -> 1255.32 | P34: =Sales_Fact[[#This Row],[Gross Amount]]*Sales_Fact[[#This Row],[Discount4]] -> 100.4256 | Q34: =IF(Sales_Fact[[#This Row],[Total_Amount5]]>1000,"High Value","Standard") -> High Value
A35: SALE33 | B35: 45620 | C35: CUST1453 | D35: PROD12 | E35: STORE6 | F35: 2 | G35: 717.31 | H35: 0.15 | I35: Credit Card | J35: 1219.427 | K35: =IF(ISBLANK(Sales_Fact[[#This Row],[Quantity]]),MEDIAN(Sales_Fact[Quantity]),Sales_Fact[[#This Row],[Quantity]]) -> 2 | L35: =IF(ISBLANK(Sales_Fact[[#This Row],[Unit_Price]]),MEDIAN(Sales_Fact[Unit_Price]),Sales_Fact[[#This Row],[Unit_Price]]) -> 717.31 | M35: =IF(ISBLANK(Sales_Fact[[#This Row],[Discount]]),MEDIAN(Sales_Fact[Discount]),Sales_Fact[[#This Row],[Discount]]) -> 0.15 | N35: =Sales_Fact[[#This Row],[Quantity2]]*Sales_Fact[[#This Row],[Unit_Price3]]*(1-Sales_Fact[[#This Row],[Discount4]]) -> 1219.427 | O35: =Sales_Fact[[#This Row],[Quantity2]]*Sales_Fact[[#This Row],[Unit_Price3]] -> 1434.62 | P35: =Sales_Fact[[#This Row],[Gross Amount]]*Sales_Fact[[#This Row],[Discount4]] -> 215.193 | Q35: =IF(Sales_Fact[[#This Row],[Total_Amount5]]>1000,"High Value","Standard") -> High Value
A36: SALE34 | B36: 45215 | C36: CUST1344 | D36: PROD79 | E36: STORE1 | G36: 873.22 | H36: 0.18 | I36: Credit Card | J36: 2148.1212 | K36: =IF(ISBLANK(Sales_Fact[[#This Row],[Quantity]]),MEDIAN(Sales_Fact[Quantity]),Sales_Fact[[#This Row],[Quantity]]) -> 2 | L36: =IF(ISBLANK(Sales_Fact[[#This Row],[Unit_Price]]),MEDIAN(Sales_Fact[Unit_Price]),Sales_Fact[[#This Row],[Unit_Price]]) -> 873.22 | M36: =IF(ISBLANK(Sales_Fact[[#This Row],[Discount]]),MEDIAN(Sales_Fact[Discount]),Sales_Fact[[#This Row],[Discount]]) -> 0.18 | N36: =Sales_Fact[[#This Row],[Quantity2]]*Sales_Fact[[#This Row],[Unit_Price3]]*(1-Sales_Fact[[#This Row],[Discount4]]) -> 1432.0808 | O36: =Sales_Fact[[#This Row],[Quantity2]]*Sales_Fact[[#This Row],[Unit_Price3]] -> 1746.44 | P36: =Sales_Fact[[#This Row],[Gross Amount]]*Sales_Fact[[#This Row],[Discount4]] -> 314.3592 | Q36: =IF(Sales_Fact[[#This Row],[Total_Amount5]]>1000,"High Value","Standard") -> High Value
A37: SALE35 | B37: 45878 | C37: CUST1218 | D37: PROD16 | E37: STORE3 | F37: 4 | G37: 109.36 | H37: 0.19 | I37: COD | J37: 354.3264 | K37: =IF(ISBLANK(Sales_Fact[[#This Row],[Quantity]]),MEDIAN(Sales_Fact[Quantity]),Sales_Fact[[#This Row],[Quantity]]) -> 4 | L37: =IF(ISBLANK(Sales_Fact[[#This Row],[Unit_Price]]),MEDIAN(Sales_Fact[Unit_Price]),Sales_Fact[[#This Row],[Unit_Price]]) -> 109.36 | M37: =IF(ISBLANK(Sales_Fact[[#This Row],[Discount]]),MEDIAN(Sales_Fact[Discount]),Sales_Fact[[#This Row],[Discount]]) -> 0.19 | N37: =Sales_Fact[[#This Row],[Quantity2]]*Sales_Fact[[#This Row],[Unit_Price3]]*(1-Sales_Fact[[#This Row],[Discount4]]) -> 354.3264 | O37: =Sales_Fact[[#This Row],[Quantity2]]*Sales_Fact[[#This Row],[Unit_Price3]] -> 437.44 | P37: =Sales_Fact[[#This Row],[Gross Amount]]*Sales_Fact[[#This Row],[Discount4]] -> 83.1136 | Q37: =IF(Sales_Fact[[#This Row],[Total_Amount5]]>1000,"High Value","Standard") -> Standard
A38: SALE36 | B38: 45635 | C38: CUST1086 | D38: PROD5 | E38: STORE7 | F38: 3 | G38: 559.52 | H38: 0.16 | I38: PayPal | J38: 1409.9904 | K38: =IF(ISBLANK(Sales_Fact[[#This Row],[Quantity]]),MEDIAN(Sales_Fact[Quantity]),Sales_Fact[[#This Row],[Quantity]]) -> 3 | L38: =IF(ISBLANK(Sales_Fact[[#This Row],[Unit_Price]]),MEDIAN(Sales_Fact[Unit_Price]),Sales_Fact[[#This Row],[Unit_Price]]) -> 559.52 | M38: =IF(ISBLANK(Sales_Fact[[#This Row],[Discount]]),MEDIAN(Sales_Fact[Discount]),Sales_Fact[[#This Row],[Discount]]) -> 0.16 | N38: =Sales_Fact[[#This Row],[Quantity2]]*Sales_Fact[[#This Row],[Unit_Price3]]*(1-Sales_Fact[[#This Row],[Discount4]]) -> 1409.9904 | O38: =Sales_Fact[[#This Row],[Quantity2]]*Sales_Fact[[#This Row],[Unit_Price3]] -> 1678.56 | P38: =Sales_Fact[[#This Row],[Gross Amount]]*Sales_Fact[[#This Row],[Discount4]] -> 268.5696 | Q38: =IF(Sales_Fact[[#This Row],[Total_Amount5]]>1000,"High Value","Standard") -> High Value
A39: SALE37 | B39: 45329 | C39: CUST1492 | D39: PROD10 | E39: STORE17 | F39: 3 | G39: 121.76 | H39: 0.27 | I39: PayPal | J39: 266.6544 | K39: =IF(ISBLANK(Sales_Fact[[#This Row],[Quantity]]),MEDIAN(Sales_Fact[Quantity]),Sales_Fact[[#This Row],[Quantity]]) -> 3 | L39: =IF(ISBLANK(Sales_Fact[[#This Row],[Unit_Price]]),MEDIAN(Sales_Fact[Unit_Price]),Sales_Fact[[#This Row],[Unit_Price]]) -> 121.76 | M39: =IF(ISBLANK(Sales_Fact[[#This Row],[Discount]]),MEDIAN(Sales_Fact[Discount]),Sales_Fact[[#This Row],[Discount]]) -> 0.27 | N39: =Sales_Fact[[#This Row],[Quantity2]]*Sales_Fact[[#This Row],[Unit_Price3]]*(1-Sales_Fact[[#This Row],[Discount4]]) -> 266.6544 | O39: =Sales_Fact[[#This Row],[Quantity2]]*Sales_Fact[[#This Row],[Unit_Price3]] -> 365.28 | P39: =Sales_Fact[[#This Row],[Gross Amount]]*Sales_Fact[[#This Row],[Discount4]] -> 98.6256 | Q39: =IF(Sales_Fact[[#This Row],[Total_Amount5]]>1000,"High Value","Standard") -> Standard
A40: SALE38 | B40: 45378 | C40: CUST1189 | D40: PROD33 | E40: STORE13 | F40: 4 | G40: 735.32 | H40: 0.06 | I40: COD | J40: 2764.8032 | K40: =IF(ISBLANK(Sales_Fact[[#This Row],[Quantity]]),MEDIAN(Sales_Fact[Quantity]),Sales_Fact[[#This Row],[Quantity]]) -> 4 | L40: =IF(ISBLANK(Sales_Fact[[#This Row],[Unit_Price]]),MEDIAN(Sales_Fact[Unit_Price]),Sales_Fact[[#This Row],[Unit_Price]]) -> 735.32 | M40: =IF(ISBLANK(Sales_Fact[[#This Row],[Discount]]),MEDIAN(Sales_Fact[Discount]),Sales_Fact[[#This Row],[Discount]]) -> 0.06 | N40: =Sales_Fact[[#This Row],[Quantity2]]*Sales_Fact[[#This Row],[Unit_Price3]]*(1-Sales_Fact[[#This Row],[Discount4]]) -> 2764.8032 | O40: =Sales_Fact[[#This Row],[Quantity2]]*Sales_Fact[[#This Row],[Unit_Price3]] -> 2941.28 | P40: =Sales_Fact[[#This Row],[Gross Amount]]*Sales_Fact[[#This Row],[Discount4]] -> 176.4768 | Q40: =IF(Sales_Fact[[#This Row],[Total_Amount5]]>1000,"High Value","Standard") -> High Value
...

Sheet Store_Dim
A1: Store_ID | B1: Store_Name | C1: Region | D1: City | E1: Store_Type | F1: Region_Storetype
A2: STORE0 | B2: Rivera-Warner | C2: East | D2: Washingtonfurt | E2: Flagship | F2: =Store_Dim[[#This Row],[Region]]&" - "&Store_Dim[[#This Row],[Store_Type]] -> East - Flagship
A3: STORE1 | B3: Martinez, Adkins and Johnson | C3: North | D3: Danielmouth | E3: Flagship | F3: =Store_Dim[[#This Row],[Region]]&" - "&Store_Dim[[#This Row],[Store_Type]] -> North - Flagship
A4: STORE2 | B4: Black-Horn | C4: South | D4: North Nancyview | E4: Outlet | F4: =Store_Dim[[#This Row],[Region]]&" - "&Store_Dim[[#This Row],[Store_Type]] -> South - Outlet
A5: STORE3 | B5: Johnson-Wright | C5: North | D5: Hoodberg | E5: Outlet | F5: =Store_Dim[[#This Row],[Region]]&" - "&Store_Dim[[#This Row],[Store_Type]] -> North - Outlet
A6: STORE4 | B6: Alexander Group | C6: South | D6: Port Sharon | E6: Online | F6: =Store_Dim[[#This Row],[Region]]&" - "&Store_Dim[[#This Row],[Store_Type]] -> South - Online
A7: STORE5 | B7: Gray Ltd | C7: North | D7: New Michaelchester | E7: Outlet | F7: =Store_Dim[[#This Row],[Region]]&" - "&Store_Dim[[#This Row],[Store_Type]] -> North - Outlet
A8: STORE6 | B8: Benson-Elliott | C8: East | D8: Port Josephberg | E8: Online | F8: =Store_Dim[[#This Row],[Region]]&" - "&Store_Dim[[#This Row],[Store_Type]] -> East - Online
A9: STORE7 | B9: Martinez-Mullins | C9: South | D9: Williamsfurt | E9: Online | F9: =Store_Dim[[#This Row],[Region]]&" - "&Store_Dim[[#This Row],[Store_Type]] -> South - Online
A10: STORE8 | B10: Bean, Jones and Park | C10: West | D10: Thompsonborough | E10: Online | F10: =Store_Dim[[#This Row],[Region]]&" - "&Store_Dim[[#This Row],[Store_Type]] -> West - Online
A11: STORE9 | B11: Moore, Padilla and Butler | C11: South | D11: East Johnstad | E11: Flagship | F11: =Store_Dim[[#This Row],[Region]]&" - "&Store_Dim[[#This Row],[Store_Type]] -> South - Flagship
A12: STORE10 | B12: Hill, Wagner and Ballard | C12: East | D12: East Davidville | E12: Online | F12: =Store_Dim[[#This Row],[Region]]&" - "&Store_Dim[[#This Row],[Store_Type]] -> East - Online
A13: STORE11 | B13: Aguirre-Keller | C13: South | D13: Lake Michael | E13: Online | F13: =Store_Dim[[#This Row],[Region]]&" - "&Store_Dim[[#This Row],[Store_Type]] -> South - Online
... A21: STORE19 | B21: Mann-Austin | C21: East | D21: Vasquezborough | E21: Online | F21: =Store_Dim[[#This Row],[Region]]&" - "&Store_Dim[[#This Row],[Store_Type]] -> East - Online

Sheet Customer_Dim
A1: Customer_ID | B1: Name | C1: Age | D1: Gender | E1: City | F1: State | G1: Country | H1: Loyalty_Level | I1: Loyalty_Level2 | J1: Name2 | K1: City2 | L1: Age Group | M1: =COUNTBLANK(Customer_Dim[Loyalty_Level]) -> 4
A2: CUST1000 | B2: sheena bonilla | C2: 55 | D2: Male | E2: Donaldton | F2: North Carolina | G2: USA | I2: =IF(ISBLANK(Customer_Dim[[#This Row],[Loyalty_Level]]),"Platinum",Customer_Dim[[#This Row],[Loyalty_Level]]) -> Platinum | J2: =PROPER(TRIM(Customer_Dim[[#This Row],[Name]])) -> Sheena Bonilla | K2: =PROPER(TRIM(Customer_Dim[[#This Row],[City]])) -> Donaldton | L2: =IF(Customer_Dim[[#This Row],[Age]]<30,"Young",IF(Customer_Dim[[#This Row],[Age]]<50,"Middle Age","Senior")) -> Senior | M2: =COUNTIF(Customer_Dim[Loyalty_Level],"Platinum") -> 145
A3: CUST1001 | B3: Eugene Nelson | C3: 26 | D3: Female | E3: Phillipsmouth | F3: North Dakota | G3: USA | H3: Platinum | I3: =IF(ISBLANK(Customer_Dim[[#This Row],[Loyalty_Level]]),"Platinum",Customer_Dim[[#This Row],[Loyalty_Level]]) -> Platinum | J3: =PROPER(TRIM(Customer_Dim[[#This Row],[Name]])) -> Eugene Nelson | K3: =PROPER(TRIM(Customer_Dim[[#This Row],[City]])) -> Phillipsmouth | L3: =IF(Customer_Dim[[#This Row],[Age]]<30,"Young",IF(Customer_Dim[[#This Row],[Age]]<50,"Middle Age","Senior")) -> Young | M3: =COUNTIF(Customer_Dim[Loyalty_Level],"Gold") -> 122
A4: CUST1002 | B4: dr. Benjamin Price | C4: 29 | D4: Female | E4: Kylebury | F4: Alabama | G4: USA | H4: Platinum | I4: =IF(ISBLANK(Customer_Dim[[#This Row],[Loyalty_Level]]),"Platinum",Customer_Dim[[#This Row],[Loyalty_Level]]) -> Platinum | J4: =PROPER(TRIM(Customer_Dim[[#This Row],[Name]])) -> Dr. Benjamin Price | K4: =PROPER(TRIM(Customer_Dim[[#This Row],[City]])) -> Kylebury | L4: =IF(Customer_Dim[[#This Row],[Age]]<30,"Young",IF(Customer_Dim[[#This Row],[Age]]<50,"Middle Age","Senior")) -> Young | M4: =COUNTIF(Customer_Dim[Loyalty_Level],"Silver") -> 104
A5: CUST1003 | B5: jeremy harris | C5: 59 | D5: Female | E5: Thomastown | F5: Ohio | G5: USA | H5: Bronze | I5: =IF(ISBLANK(Customer_Dim[[#This Row],[Loyalty_Level]]),"Platinum",Customer_Dim[[#This Row],[Loyalty_Level]]) -> Bronze | J5: =PROPER(TRIM(Customer_Dim[[#This Row],[Name]])) -> Jeremy Harris | K5: =PROPER(TRIM(Customer_Dim[[#This Row],[City]])) -> Thomastown | L5: =IF(Customer_Dim[[#This Row],[Age]]<30,"Young",IF(Customer_Dim[[#This Row],[Age]]<50,"Middle Age","Senior")) -> Senior | M5: =COUNTIF(Customer_Dim[Loyalty_Level],"Bronze") -> 125
A6: CUST1004 | B6: Caroline Collins | C6: 64 | D6: Female | E6: Nicholasshire | F6: California | G6: USA | H6: Silver | I6: =IF(ISBLANK(Customer_Dim[[#This Row],[Loyalty_Level]]),"Platinum",Customer_Dim[[#This Row],[Loyalty_Level]]) -> Silver | J6: =PROPER(TRIM(Customer_Dim[[#This Row],[Name]])) -> Caroline Collins | K6: =PROPER(TRIM(Customer_Dim[[#This Row],[City]])) -> Nicholasshire | L6: =IF(Customer_Dim[[#This Row],[Age]]<30,"Young",IF(Customer_Dim[[#This Row],[Age]]<50,"Middle Age","Senior")) -> Senior
A7: CUST1005 | B7: Christine Vaughn | C7: 24 | D7: Male | E7: East Amandamouth | F7: Oregon | G7: USA | H7: Bronze | I7: =IF(ISBLANK(Customer_Dim[[#This Row],[Loyalty_Level]]),"Platinum",Customer_Dim[[#This Row],[Loyalty_Level]]) -> Bronze | J7: =PROPER(TRIM(Customer_Dim[[#This Row],[Name]])) -> Christine Vaughn | K7: =PROPER(TRIM(Customer_Dim[[#This Row],[City]])) -> East Amandamouth | L7: =IF(Customer_Dim[[#This Row],[Age]]<30,"Young",IF(Customer_Dim[[#This Row],[Age]]<50,"Middle Age","Senior")) -> Young
A8: CUST1006 | B8: Amber Jackson | C8: 29 | D8: Female | E8: Deborahborough | F8: South Dakota | G8: USA | H8: Platinum | I8: =IF(ISBLANK(Customer_Dim[[#This Row],[Loyalty_Level]]),"Platinum",Customer_Dim[[#This Row],[Loyalty_Level]]) -> Platinum | J8: =PROPER(TRIM(Customer_Dim[[#This Row],[Name]])) -> Amber Jackson | K8: =PROPER(TRIM(Customer_Dim[[#This Row],[City]])) -> Deborahborough | L8: =IF(Customer_Dim[[#This Row],[Age]]<30,"Young",IF(Customer_Dim[[#This Row],[Age]]<50,"Middle Age","Senior")) -> Young
A9: CUST1007 | B9: Daniel Boyd | C9: 29 | D9: Female | E9: West Pamelafurt | F9: West Virginia | G9: USA | H9: Bronze | I9: =IF(ISBLANK(Customer_Dim[[#This Row],[Loyalty_Level]]),"Platinum",Customer_Dim[[#This Row],[Loyalty_Level]]) -> Bronze | J9: =PROPER(TRIM(Customer_Dim[[#This Row],[Name]])) -> Daniel Boyd | K9: =PROPER(TRIM(Customer_Dim[[#This Row],[City]])) -> West Pamelafurt | L9: =IF(Customer_Dim[[#This Row],[Age]]<30,"Young",IF(Customer_Dim[[#This Row],[Age]]<50,"Middle Age","Senior")) -> Young
A10: CUST1008 | B10: Melissa Howard | C10: 53 | D10: Female | E10: Maynardton | F10: New Hampshire | G10: USA | H10: Gold | I10: =IF(ISBLANK(Customer_Dim[[#This Row],[Loyalty_Level]]),"Platinum",Customer_Dim[[#This Row],[Loyalty_Level]]) -> Gold | J10: =PROPER(TRIM(Customer_Dim[[#This Row],[Name]])) -> Melissa Howard | K10: =PROPER(TRIM(Customer_Dim[[#This Row],[City]])) -> Maynardton | L10: =IF(Customer_Dim[[#This Row],[Age]]<30,"Young",IF(Customer_Dim[[#This Row],[Age]]<50,"Middle Age","Senior")) -> Senior
A11: CUST1009 | B11: Ms. Maria Leach | C11: 64 | D11: Male | E11: Melissashire | F11: Pennsylvania | G11: USA | H11: Platinum | I11: =IF(ISBLANK(Customer_Dim[[#This Row],[Loyalty_Level]]),"Platinum",Customer_Dim[[#This Row],[Loyalty_Level]]) -> Platinum | J11: =PROPER(TRIM(Customer_Dim[[#This Row],[Name]])) -> Ms. Maria Leach | K11: =PROPER(TRIM(Customer_Dim[[#This Row],[City]])) -> Melissashire | L11: =IF(Customer_Dim[[#This Row],[Age]]<30,"Young",IF(Customer_Dim[[#This Row],[Age]]<50,"Middle Age","Senior")) -> Senior
A12: CUST1010 | B12: Dominic Page | C12: 53 | D12: Male | E12: Port Michaelburgh | F12: Pennsylvania | G12: USA | H12: Bronze | I12: =IF(ISBLANK(Customer_Dim[[#This Row],[Loyalty_Level]]),"Platinum",Customer_Dim[[#This Row],[Loyalty_Level]]) -> Bronze | J12: =PROPER(TRIM(Customer_Dim[[#This Row],[Name]])) -> Dominic Page | K12: =PROPER(TRIM(Customer_Dim[[#This Row],[City]])) -> Port Michaelburgh | L12: =IF(Customer_Dim[[#This Row],[Age]]<30,"Young",IF(Customer_Dim[[#This Row],[Age]]<50,"Middle Age","Senior")) -> Senior
A13: CUST1011 | B13: Brian Lopez | C13: 28 | D13: Female | E13: East Krista | F13: New York | G13: USA | H13: Gold | I13: =IF(ISBLANK(Customer_Dim[[#This Row],[Loyalty_Level]]),"Platinum",Customer_Dim[[#This Row],[Loyalty_Level]]) -> Gold | J13: =PROPER(TRIM(Customer_Dim[[#This Row],[Name]])) -> Brian Lopez | K13: =PROPER(TRIM(Customer_Dim[[#This Row],[City]])) -> East Krista | L13: =IF(Customer_Dim[[#This Row],[Age]]<30,"Young",IF(Customer_Dim[[#This Row],[Age]]<50,"Middle Age","Senior")) -> Young
A14: CUST1012 | B14: Kenneth Lambert | C14: 55 | D14: Female | E14: North Kathryn | F14: Kansas | G14: USA | H14: Platinum | I14: =IF(ISBLANK(Customer_Dim[[#This Row],[Loyalty_Level]]),"Platinum",Customer_Dim[[#This Row],[Loyalty_Level]]) -> Platinum | J14: =PROPER(TRIM(Customer_Dim[[#This Row],[Name]])) -> Kenneth Lambert | K14: =PROPER(TRIM(Customer_Dim[[#This Row],[City]])) -> North Kathryn | L14: =IF(Customer_Dim[[#This Row],[Age]]<30,"Young",IF(Customer_Dim[[#This Row],[Age]]<50,"Middle Age","Senior")) -> Senior
A15: CUST1013 | B15: Nathan Hernandez | C15: 32 | D15: Female | E15: New Becky | F15: Montana | G15: USA | H15: Silver | I15: =IF(ISBLANK(Customer_Dim[[#This Row],[Loyalty_Level]]),"Platinum",Customer_Dim[[#This Row],[Loyalty_Level]]) -> Silver | J15: =PROPER(TRIM(Customer_Dim[[#This Row],[Name]])) -> Nathan Hernandez | K15: =PROPER(TRIM(Customer_Dim[[#This Row],[City]])) -> New Becky | L15: =IF(Customer_Dim[[#This Row],[Age]]<30,"Young",IF(Customer_Dim[[#This Row],[Age]]<50,"Middle Age","Senior")) -> Middle Age
A16: CUST1014 | B16: Ashley Cohen | C16: 53 | D16: Female | E16: Lake Kristamouth | F16: Nebraska | G16: USA | H16: Silver | I16: =IF(ISBLANK(Customer_Dim[[#This Row],[Loyalty_Level]]),"Platinum",Customer_Dim[[#This Row],[Loyalty_Level]]) -> Silver | J16: =PROPER(TRIM(Customer_Dim[[#This Row],[Name]])) -> Ashley Cohen | K16: =PROPER(TRIM(Customer_Dim[[#This Row],[City]])) -> Lake Kristamouth | L16: =IF(Customer_Dim[[#This Row],[Age]]<30,"Young",IF(Customer_Dim[[#This Row],[Age]]<50,"Middle Age","Senior")) -> Senior
A17: CUST1015 | B17: Laura Alvarez | C17: 49 | D17: Female | E17: Lawsonhaven | F17: Washington | G17: USA | H17: Platinum | I17: =IF(ISBLANK(Customer_Dim[[#This Row],[Loyalty_Level]]),"Platinum",Customer_Dim[[#This Row],[Loyalty_Level]]) -> Platinum | J17: =PROPER(TRIM(Customer_Dim[[#This Row],[Name]])) -> Laura Alvarez | K17: =PROPER(TRIM(Customer_Dim[[#This Row],[City]])) -> Lawsonhaven | L17: =IF(Customer_Dim[[#This Row],[Age]]<30,"Young",IF(Customer_Dim[[#This Row],[Age]]<50,"Middle Age","Senior")) -> Middle Age
... A19: CUST1017 | B19: Adam Cruz | C19: 60 | D19: Female | E19: Brandonville | F19: Georgia | G19: USA | H19: Platinum | I19: =IF(ISBLANK(Customer_Dim[[#This Row],[Loyalty_Level]]),"Platinum",Customer_Dim[[#This Row],[Loyalty_Level]]) -> Platinum | J19: =PROPER(TRIM(Customer_Dim[[#This Row],[Name]])) -> Adam Cruz | K19: =PROPER(TRIM(Customer_Dim[[#This Row],[City]])) -> Brandonville | L19: =IF(Customer_Dim[[#This Row],[Age]]<30,"Young",IF(Customer_Dim[[#This Row],[Age]]<50,"Middle Age","Senior")) -> Senior
A20: CUST1018 | B20: Rhonda Moss | C20: 43 | D20: Male | E20: South William | F20: Kansas | G20: USA | I20: =IF(ISBLANK(Customer_Dim[[#This Row],[Loyalty_Level]]),"Platinum",Customer_Dim[[#This Row],[Loyalty_Level]]) -> Platinum | J20: =PROPER(TRIM(Customer_Dim[[#This Row],[Name]])) -> Rhonda Moss | K20: =PROPER(TRIM(Customer_Dim[[#This Row],[City]])) -> South William | L20: =IF(Customer_Dim[[#This Row],[Age]]<30,"Young",IF(Customer_Dim[[#This Row],[Age]]<50,"Middle Age","Senior")) -> Middle Age
A21: CUST1019 | B21: Michael Torres | C21: 46 | D21: Female | E21: Gonzalezfort | F21: New Jersey | G21: USA | H21: Platinum | I21: =IF(ISBLANK(Customer_Dim[[#This Row],[Loyalty_Level]]),"Platinum",Customer_Dim[[#This Row],[Loyalty_Level]]) -> Platinum | J21: =PROPER(TRIM(Customer_Dim[[#This Row],[Name]])) -> Michael Torres | K21: =PROPER(TRIM(Customer_Dim[[#This Row],[City]])) -> Gonzalezfort | L21: =IF(Customer_Dim[[#This Row],[Age]]<30,"Young",IF(Customer_Dim[[#This Row],[Age]]<50,"Middle Age","Senior")) -> Middle Age
A22: CUST1020 | B22: Bridget Allen | C22: 59 | D22: Male | E22: Lake Shaneburgh | F22: Delaware | G22: USA | H22: Silver | I22: =IF(ISBLANK(Customer_Dim[[#This Row],[Loyalty_Level]]),"Platinum",Customer_Dim[[#This Row],[Loyalty_Level]]) -> Silver | J22: =PROPER(TRIM(Customer_Dim[[#This Row],[Name]])) -> Bridget Allen | K22: =PROPER(TRIM(Customer_Dim[[#This Row],[City]])) -> Lake Shaneburgh | L22: =IF(Customer_Dim[[#This Row],[Age]]<30,"Young",IF(Customer_Dim[[#This Row],[Age]]<50,"Middle Age","Senior")) -> Senior
A23: CUST1021 | B23: Jeff Martinez | C23: 36 | D23: Female | E23: Smithburgh | F23: Oklahoma | G23: USA | H23: Gold | I23: =IF(ISBLANK(Customer_Dim[[#This Row],[Loyalty_Level]]),"Platinum",Customer_Dim[[#This Row],[Loyalty_Level]]) -> Gold | J23: =PROPER(TRIM(Customer_Dim[[#This Row],[Name]])) -> Jeff Martinez | K23: =PROPER(TRIM(Customer_Dim[[#This Row],[City]])) -> Smithburgh | L23: =IF(Customer_Dim[[#This Row],[Age]]<30,"Young",IF(Customer_Dim[[#This Row],[Age]]<50,"Middle Age","Senior")) -> Middle Age
A24: CUST1022 | B24: paul fox | C24: 33 | D24: Female | E24: Michaelton | F24: Hawaii | G24: USA | H24: Silver | I24: =IF(ISBLANK(Customer_Dim[[#This Row],[Loyalty_Level]]),"Platinum",Customer_Dim[[#This Row],[Loyalty_Level]]) -> Silver | J24: =PROPER(TRIM(Customer_Dim[[#This Row],[Name]])) -> Paul Fox | K24: =PROPER(TRIM(Customer_Dim[[#This Row],[City]])) -> Michaelton | L24: =IF(Customer_Dim[[#This Row],[Age]]<30,"Young",IF(Customer_Dim[[#This Row],[Age]]<50,"Middle Age","Senior")) -> Middle Age
A25: CUST1023 | B25: Jonathan Steele | C25: 52 | D25: Female | E25: Molinabury | F25: Oregon | G25: USA | H25: Silver | I25: =IF(ISBLANK(Customer_Dim[[#This Row],[Loyalty_Level]]),"Platinum",Customer_Dim[[#This Row],[Loyalty_Level]]) -> Silver | J25: =PROPER(TRIM(Customer_Dim[[#This Row],[Name]])) -> Jonathan Steele | K25: =PROPER(TRIM(Customer_Dim[[#This Row],[City]])) -> Molinabury | L25: =IF(Customer_Dim[[#This Row],[Age]]<30,"Young",IF(Customer_Dim[[#This Row],[Age]]<50,"Middle Age","Senior")) -> Senior
A26: CUST1024 | B26: Heather Collins | C26: 40 | D26: Male | E26: Rogerschester | F26: Idaho | G26: USA | H26: Platinum | I26: =IF(ISBLANK(Customer_Dim[[#This Row],[Loyalty_Level]]),"Platinum",Customer_Dim[[#This Row],[Loyalty_Level]]) -> Platinum | J26: =PROPER(TRIM(Customer_Dim[[#This Row],[Name]])) -> Heather Collins | K26: =PROPER(TRIM(Customer_Dim[[#This Row],[City]])) -> Rogerschester | L26: =IF(Customer_Dim[[#This Row],[Age]]<30,"Young",IF(Customer_Dim[[#This Row],[Age]]<50,"Middle Age","Senior")) -> Middle Age
A27: CUST1025 | B27: Diana Taylor | C27: 59 | D27: Female | E27: Vasqueztown | F27: California | G27: USA | H27: Bronze | I27: =IF(ISBLANK(Customer_Dim[[#This Row],[Loyalty_Level]]),"Platinum",Customer_Dim[[#This Row],[Loyalty_Level]]) -> Bronze | J27: =PROPER(TRIM(Customer_Dim[[#This Row],[Name]])) -> Diana Taylor | K27: =PROPER(TRIM(Customer_Dim[[#This Row],[City]])) -> Vasqueztown | L27: =IF(Customer_Dim[[#This Row],[Age]]<30,"Young",IF(Customer_Dim[[#This Row],[Age]]<50,"Middle Age","Senior")) -> Senior
A28: CUST1026 | B28: Amber Carlson | C28: 18 | D28: Female | E28: East Michellemouth | F28: Missouri | G28: USA | H28: Gold | I28: =IF(ISBLANK(Customer_Dim[[#This Row],[Loyalty_Level]]),"Platinum",Customer_Dim[[#This Row],[Loyalty_Level]]) -> Gold | J28: =PROPER(TRIM(Customer_Dim[[#This Row],[Name]])) -> Amber Carlson | K28: =PROPER(TRIM(Customer_Dim[[#This Row],[City]])) -> East Michellemouth | L28: =IF(Customer_Dim[[#This Row],[Age]]<30,"Young",IF(Customer_Dim[[#This Row],[Age]]<50,"Middle Age","Senior")) -> Young
A29: CUST1027 | B29: Leslie Johnson | C29: 31 | D29: Male | E29: Mollyshire | F29: Utah | G29: USA | I29: =IF(ISBLANK(Customer_Dim[[#This Row],[Loyalty_Level]]),"Platinum",Customer_Dim[[#This Row],[Loyalty_Level]]) -> Platinum | J29: =PROPER(TRIM(Customer_Dim[[#This Row],[Name]])) -> Leslie Johnson | K29: =PROPER(TRIM(Customer_Dim[[#This Row],[City]])) -> Mollyshire | L29: =IF(Customer_Dim[[#This Row],[Age]]<30,"Young",IF(Customer_Dim[[#This Row],[Age]]<50,"Middle Age","Senior")) -> Middle Age
A30: CUST1028 | B30: Joshua Ryan | C30: 27 | D30: Female | E30: New David | F30: New Jersey | G30: USA | H30: Platinum | I30: =IF(ISBLANK(Customer_Dim[[#This Row],[Loyalty_Level]]),"Platinum",Customer_Dim[[#This Row],[Loyalty_Level]]) -> Platinum | J30: =PROPER(TRIM(Customer_Dim[[#This Row],[Name]])) -> Joshua Ryan | K30: =PROPER(TRIM(Customer_Dim[[#This Row],[City]])) -> New David | L30: =IF(Customer_Dim[[#This Row],[Age]]<30,"Young",IF(Customer_Dim[[#This Row],[Age]]<50,"Middle Age","Senior")) -> Young
A31: CUST1029 | B31: David Arnold | C31: 54 | D31: Female | E31: East Jennifer | F31: California | G31: USA | H31: Silver | I31: =IF(ISBLANK(Customer_Dim[[#This Row],[Loyalty_Level]]),"Platinum",Customer_Dim[[#This Row],[Loyalty_Level]]) -> Silver | J31: =PROPER(TRIM(Customer_Dim[[#This Row],[Name]])) -> David Arnold | K31: =PROPER(TRIM(Customer_Dim[[#This Row],[City]])) -> East Jennifer | L31: =IF(Customer_Dim[[#This Row],[Age]]<30,"Young",IF(Customer_Dim[[#This Row],[Age]]<50,"Middle Age","Senior")) -> Senior
A32: CUST1030 | B32: Jessica Acevedo | C32: 64 | D32: Female | E32: Amybury | F32: Pennsylvania | G32: USA | H32: Bronze | I32: =IF(ISBLANK(Customer_Dim[[#This Row],[Loyalty_Level]]),"Platinum",Customer_Dim[[#This Row],[Loyalty_Level]]) -> Bronze | J32: =PROPER(TRIM(Customer_Dim[[#This Row],[Name]])) -> Jessica Acevedo | K32: =PROPER(TRIM(Customer_Dim[[#This Row],[City]])) -> Amybury | L32: =IF(Customer_Dim[[#This Row],[Age]]<30,"Young",IF(Customer_Dim[[#This Row],[Age]]<50,"Middle Age","Senior")) -> Senior
A33: CUST1031 | B33: Sarah Vance | C33: 41 | D33: Male | E33: Johnsonville | F33: Oregon | G33: USA | H33: Silver | I33: =IF(ISBLANK(Customer_Dim[[#This Row],[Loyalty_Level]]),"Platinum",Customer_Dim[[#This Row],[Loyalty_Level]]) -> Silver | J33: =PROPER(TRIM(Customer_Dim[[#This Row],[Name]])) -> Sarah Vance | K33: =PROPER(TRIM(Customer_Dim[[#This Row],[City]])) -> Johnsonville | L33: =IF(Customer_Dim[[#This Row],[Age]]<30,"Young",IF(Customer_Dim[[#This Row],[Age]]<50,"Middle Age","Senior")) -> Middle Age
A34: CUST1032 | B34: Mike Jennings | C34: 48 | D34: Female | E34: Fostermouth | F34: Arizona | G34: USA | H34: Gold | I34: =IF(ISBLANK(Customer_Dim[[#This Row],[Loyalty_Level]]),"Platinum",Customer_Dim[[#This Row],[Loyalty_Level]]) -> Gold | J34: =PROPER(TRIM(Customer_Dim[[#This Row],[Name]])) -> Mike Jennings | K34: =PROPER(TRIM(Customer_Dim[[#This Row],[City]])) -> Fostermouth | L34: =IF(Customer_Dim[[#This Row],[Age]]<30,"Young",IF(Customer_Dim[[#This Row],[Age]]<50,"Middle Age","Senior")) -> Middle Age
A35: CUST1033 | B35: Robert Jones DDS | C35: 25 | D35: Male | E35: Tristanton | F35: Oklahoma | G35: USA | H35: Platinum | I35: =IF(ISBLANK(Customer_Dim[[#This Row],[Loyalty_Level]]),"Platinum",Customer_Dim[[#This Row],[Loyalty_Level]]) -> Platinum | J35: =PROPER(TRIM(Customer_Dim[[#This Row],[Name]])) -> Robert Jones Dds | K35: =PROPER(TRIM(Customer_Dim[[#This Row],[City]])) -> Tristanton | L35: =IF(Customer_Dim[[#This Row],[Age]]<30,"Young",IF(Customer_Dim[[#This Row],[Age]]<50,"Middle Age","Senior")) -> Young
A36: CUST1034 | B36: Christopher Olson | C36: 27 | D36: Female | E36: West Richard | F36: Maryland | G36: USA | H36: Platinum | I36: =IF(ISBLANK(Customer_Dim[[#This Row],[Loyalty_Level]]),"Platinum",Customer_Dim[[#This Row],[Loyalty_Level]]) -> Platinum | J36: =PROPER(TRIM(Customer_Dim[[#This Row],[Name]])) -> Christopher Olson | K36: =PROPER(TRIM(Customer_Dim[[#This Row],[City]])) -> West Richard | L36: =IF(Customer_Dim[[#This Row],[Age]]<30,"Young",IF(Customer_Dim[[#This Row],[Age]]<50,"Middle Age","Senior")) -> Young
A37: CUST1035 | B37: Rachel Myers | C37: 52 | D37: Male | E37: Robertberg | F37: North Dakota | G37: USA | H37: Silver | I37: =IF(ISBLANK(Customer_Dim[[#This Row],[Loyalty_Level]]),"Platinum",Customer_Dim[[#This Row],[Loyalty_Level]]) -> Silver | J37: =PROPER(TRIM(Customer_Dim[[#This Row],[Name]])) -> Rachel Myers | K37: =PROPER(TRIM(Customer_Dim[[#This Row],[City]])) -> Robertberg | L37: =IF(Customer_Dim[[#This Row],[Age]]<30,"Young",IF(Customer_Dim[[#This Row],[Age]]<50,"Middle Age","Senior")) -> Senior
A38: CUST1036 | B38: Thomas Phillips | C38: 20 | D38: Female | E38: Luisfurt | F38: Georgia | G38: USA | H38: Gold | I38: =IF(ISBLANK(Customer_Dim[[#This Row],[Loyalty_Level]]),"Platinum",Customer_Dim[[#This Row],[Loyalty_Level]]) -> Gold | J38: =PROPER(TRIM(Customer_Dim[[#This Row],[Name]])) -> Thomas Phillips | K38: =PROPER(TRIM(Customer_Dim[[#This Row],[City]])) -> Luisfurt | L38: =IF(Customer_Dim[[#This Row],[Age]]<30,"Young",IF(Customer_Dim[[#This Row],[Age]]<50,"Middle Age","Senior")) -> Young
A39: CUST1037 | B39: Christopher Carter | C39: 27 | D39: Female | E39: Brendastad | F39: South Dakota | G39: USA | I39: =IF(ISBLANK(Customer_Dim[[#This Row],[Loyalty_Level]]),"Platinum",Customer_Dim[[#This Row],[Loyalty_Level]]) -> Platinum | J39: =PROPER(TRIM(Customer_Dim[[#This Row],[Name]])) -> Christopher Carter | K39: =PROPER(TRIM(Customer_Dim[[#This Row],[City]])) -> Brendastad | L39: =IF(Customer_Dim[[#This Row],[Age]]<30,"Young",IF(Customer_Dim[[#This Row],[Age]]<50,"Middle Age","Senior")) -> Young
A40: CUST1038 | B40: Deanna Simpson | C40: 35 | D40: Female | E40: Brownport | F40: North Dakota | G40: USA | H40: Bronze | I40: =IF(ISBLANK(Customer_Dim[[#This Row],[Loyalty_Level]]),"Platinum",Customer_Dim[[#This Row],[Loyalty_Level]]) -> Bronze | J40: =PROPER(TRIM(Customer_Dim[[#This Row],[Name]])) -> Deanna Simpson | K40: =PROPER(TRIM(Customer_Dim[[#This Row],[City]])) -> Brownport | L40: =IF(Customer_Dim[[#This Row],[Age]]<30,"Young",IF(Customer_Dim[[#This Row],[Age]]<50,"Middle Age","Senior")) -> Middle Age
A41: CUST1039 | B41: Tonya Reynolds | C41: 55 | D41: Female | E41: Darleneton | F41: Michigan | G41: USA | H41: Gold | I41: =IF(ISBLANK(Customer_Dim[[#This Row],[Loyalty_Level]]),"Platinum",Customer_Dim[[#This Row],[Loyalty_Level]]) -> Gold | J41: =PROPER(TRIM(Customer_Dim[[#This Row],[Name]])) -> Tonya Reynolds | K41: =PROPER(TRIM(Customer_Dim[[#This Row],[City]])) -> Darleneton | L41: =IF(Customer_Dim[[#This Row],[Age]]<30,"Young",IF(Customer_Dim[[#This Row],[Age]]<50,"Middle Age","Senior")) -> Senior
...

Sheet Product_Dim
